---
title: 3 February, 2016
bg: "diary-7.jpg"
layout: post
crawlertitle: "3 February, 2016"
summary: "promise"
date: Tue May 30 2017 11:27:22 GMT+0800 (CST)
categories: "diary"
type: diary
author: YDSS
---

## promise

### promise里throw Error

> Promise的构造函数，以及被 then 调用执行的函数基本上都可以认为是在 try...catch 代码块中执行的，所以在这些代码中即使使用 throw ，程序本身也不会因为异常而终止。

意思是：即使在Promise结构里`throw`了error，后面的代码（这里指Promise结构外的代码，后面的`then`都不会执行）依旧会执行。这些error都会流转到`catch`方法中，如果一定要把报错抛出来，可以在`catch`中`throw`

```js
// 测试在promise结构体中抛出error是否真能抛出去
function testThrowErrorInPromise() {
    let p = Promise.resolve();

    p.then(() => {
        throw new Error('hahhah');
    })
        .catch(err => {
            console.log('error in catch: ' + err.message);
            throw err;
        });

    console.log('conutine...');
}

testThrowErrorInPromise();
```

