---
title: 8 July, 2016
bg: "diary-6.jpg"
layout: post
crawlertitle: "8 July, 2016"
summary: "异常处理"
date: Tue May 30 2017 11:27:22 GMT+0800 (CST)
categories: "diary"
type: diary
author: YDSS
---

### 异常处理

co中有两个地方处理了异常：

1. 在`onFullfilled`函数里：

	```js
	function onFulfilled(res) {
	  var ret;
	  try {
	    ret = gen.next(res);
	  } catch (e) {
	    return reject(e);
	  }
	  next(ret);
	}
	```
	
	这里的catch捕获**相邻的两个`yield`之前的代码可能抛出的异常**。举个栗子：
	
	```js
	// test exception flow
	function* funA() {
	    return 1;
	}
	
	function* funB() {
	    return 2;
	}
	
	co(function* () {
	    let a = yield funA(); // line 1
	
	    console.log(c); // line 2
	
	    let b = yield funB(); // line 3
	}).then(res => {
	    console.log('res');
	}, err => {
	    console.log('err: ' + err); // line 4
	});
	```
	很明显line 2会抛错。而捕获这个exception的地方在line 1的yield与line 2的yield之间需要执行的`gen.next`处，也就是onFullfilled方法里。错误会通过promise的reject抛出，也即是在line 4被打印出来
	
2. 第二处在`onRejected`函数中：

	```js
	function onRejected(err) {
	  var ret;
	  try {
	    ret = gen.throw(err);
	  } catch (e) {
	    return reject(e);
	  }
	  next(ret);
	}
	```
	
	onRejected在`next`函数中被执行：
	
	```js
	function next(ret) {
	  if (ret.done) return resolve(ret.value);
	  var value = toPromise.call(ctx, ret.value);
	  // value为promise对象会调用onRejected，如果value执行过程中有报错的话
	  if (value && isPromise(value)) return value.then(onFulfilled, onRejected);
	  return onRejected(new TypeError('You may only yield a function, promise, generator, array, or object, '
	    + 'but the following object was passed: "' + String(ret.value) + '"'));
	}
	```
	可以看到onRejected在value也就是co generator函数体中yield右侧的函数，执行之后通过promise的reject方法接收异常。还是以上面的栗子为例：
	
	```js
	function* funA() {
	    console.log(a); // line 1
	    return 1;
	}
	
	function* funB() {
	    return 2;
	}
	
	co(function* () {
	    let a = yield funA(); // line 2
	
	    let b = yield funB(); // line 3
	}).then(res => {
	    console.log('res');
	}, err => {
	    console.log('err: ' + err); // line 4
	});
	```
	line 1会报错，这个错会通过promise的reject方法传给onRejected函数，onRejected函数再通过`gen.throw`把error传回co的generator函数体，也就是`co(function* () {...})`中的内容，这个报错同样也在line 4打印出来。这就是co的巧妙之处，把两个地方的报错汇集到一处接收，对用户透明。
	
	**没看懂的一个地方是onRejected方法为什么也要catch一次，难道`gen.throw`也可能抛错吗？**

### thunk函数

thunk函数，有的地方又叫偏函数（不过这个偏函数跟数学中的概念完全不同），与`curry`的概念有些相似：thunk函数有两个特点，一是只有一个参数，参数为callback；二是callback参数符合nodejs的callback风格，即`callback(err, result)`。当有函数存在多个参数，且需要通过callback返回结果时，可以用thunk函数接收非callback的参数，返回以callback为参数的函数。

举个栗子：

```js
// cb为callback参数
function test(a, cb) {
    return cb(null, a);
}

function thunk(cb) {
    // 这里已经加上了第一个参数
    return test(2, cb);
}
```

自己写了一个thunk转成promise的函数，跟co中的类似：

```js
function thunkToPromise(fn) {
    return new Promise((resolve, reject) => {
        fn((err, ret) => {
            if (err) return reject(err);
            resolve(ret);
        });
    });
}
```
